Workbook

Sheet Cover Page 
A1: MR PRICE GROUP (MRP)
A3: Equity Research & DCF Valuation Model
A4: Integrated 3-Statement Financial Model, DCF Valuation & Sensitivity Analysis
A6: Company Snapshot
A7: Sector: Retail Apparell
A8: Exchange: JSE
A9: Currency: ZAR (R'm)
A10: Valuation Method: DCF (FCFF)
A11: Forecast Period: FY2026 - FY2030
A13: Project Overview
A14: This project develops an integrated financial model and discounted cash flow valuation for Mr Price Group. The model includes historical financial statement analysis, forecast modelling, working capital schedules, DCF valuation, scenario analysis, and operational sensitivity testing
A20: Key Features
... A30: Key Valuation Output
A32: Metric | B32: Value
A33: Base Case Implied Share Price | B33: =219 -> 219
A34: Current Market Price (as at 26 May 2026) | B34: 156.52
A35: Base Case Upside | B35: 0.402
A36: WACC | B36: 0.1385
A37: Terminal Growth Rate | B37: 0.03
A38: Market data and valuation assumptions as at 26 May 2026.
A55: Prepared By: Buzwekazi George Prepared as part of a financial modelling portfolio project (2026)

Sheet Dashboard
X1: Scenario | Y1: Value
B2: MR PRICE GROUP (MRP) - VALUATION DASHBOARD | X2: Bear Case | Y2: =206 -> 206
B3: Scenario Selection & Key Valuation Outputs | X3: Base Case | Y3: =219 -> 219
X4: Bull Case | Y4: =230 -> 230
B5: Scenario Selection | X5: Market Price | Y5: =156.52 -> 156.52
B6: 1. Select Scenario | C6: 2
C7: =IF(C6=1,"Bull Case: High Growth / Low WACC",IF(C6=2,"Base Case: Current Market View","Bear Case: Recessionary / High WACC")) -> Base Case: Current Market View
B10: Intrinsic Value Summary
B11: Implied Equity Value per Share: | C11: ='DCF Valuation'!B34 -> 219.48848
B12: Current Market Price (MRP): | C12: =156.52 -> 156.52
B13: (As at 26 May 2026)
B14: Total Upside / (Downside) | C14: =(C11/C12)-1 -> 0.4023031
B17: Live Scenario Assumptions
B18: Revenue Growth Adjustment | C18: =Assumptions!B249 -> 0
B19: Operating Expense (OpEx) Adjustment | C19: =Assumptions!B250 -> 0
B20: WACC / Discount Rate Adjustment | C20: =Assumptions!B251 -> 0
B21: Terminal Growth (g) Adjustment | C21: =Assumptions!B252 -> 0
B44: Investment View The valuation suggests that Mr Price may be undervalued relative to the current market price, supported by steady revenue growth, resilient cash generation, and gradual margin recovery over the forecast period. However, the valuation remains sensitive to long-term growth assumptions, operating cost pressures, and South African consumer spending conditions.

Sheet Assumptions
A2: CAPEX Assumption
A4: Driver | B4: Value
A5: CAPEX as % of Revenue | B5: 0.015
A8: CAPEX Intensity Analysis (% of Revenue)
A9: R'm (Group) | B9: FY2021 | C9: FY2022 | D9: FY2023 | E9: FY2024 | F9: FY2025
A10: Revenue | B10: 22827 | C10: 28083 | D10: 32853 | E10: 37944 | F10: 40933
A11: CAPEX (Additions) | B11: =B23 -> 296 | C11: =C23 -> 580 | D11: =D23 -> 756 | E11: =E23 -> 915 | F11: =F23 -> 797
A12: CAPEX/ Revenue (%) | B12: =B11/B10 -> 0.0129671 | C12: =C11/C10 -> 0.020653064 | D12: =D11/D10 -> 0.023011597 | E12: =E11/E10 -> 0.024114485 | F12: =F11/F10 -> 0.019470843
A13: Historical range: 1,3% - 2,4%
A15: Supporting Analysis - CAPEX
A16: CAPEX= Ending PPE + Depreciation - Beginning PPE
A17: R'm (Group) | B17: FY2021 | C17: FY2022 | D17: FY2023 | E17: FY2024 | F17: FY2025 (Calculated)
A18: Ending PPE | B18: 2236 | C18: 2518 | D18: 3598 | E18: 4072 | F18: 4254
A19: Beginning PPE | B19: 2137 | C19: 2236 | D19: 2518 | E19: 3598 | F19: 4072
A20: Change in PPE | B20: =B18-B19 -> 99 | C20: =C18-C19 -> 282 | D20: =D18-D19 -> 1080 | E20: =E18-E19 -> 474 | F20: =F18-F19 -> 182
A21: Depreciation | B21: 321 | C21: 320 | D21: 355 | E21: 538 | F21: 578
A22: CAPEX (Calculated) | B22: =SUM(B20,B21) -> 420 | C22: =SUM(C20,C21) -> 602 | D22: =SUM(D20,D21) -> 1435 | E22: =SUM(E20,E21) -> 1012 | F22: =SUM(F20,F21) -> 760
A23: CAPEX (Reported) | B23: 296 | C23: 580 | D23: 756 | E23: 915 | F23: 797
A24: Difference | B24: =B22-B23 -> 124 | C24: =C22-C23 -> 22 | D24: =D22-D23 -> 679 | E24: =E22-E23 -> 97 | F24: =F22-F23 -> -37
A27: Depreciation Assumption
A29: Driver | B29: Value
A30: Depreciation (% of PPE) | B30: =14% -> 0.14
A33: Depreciation Rate Analysis (% of PPE)
B34: FY2021 | C34: FY2022 | D34: FY2023 | E34: FY2024 | F34: FY2025
A35: Depreciation | B35: =B21 -> 321 | C35: =C21 -> 320 | D35: =D21 -> 355 | E35: =E21 -> 538 | F35: =F21 -> 578
A36: Average PPE | B36: =(B19+B18)/2 -> 2186.5 | C36: =(C19+C18)/2 -> 2377 | D36: =(D19+D18)/2 -> 3058 | E36: =(E19+E18)/2 -> 3835 | F36: =(F19+F18)/2 -> 4163
A37: Depreciation % | B37: =B35/B36 -> 0.14680997 | C37: =C35/C36 -> 0.13462347 | D37: =D35/D36 -> 0.11608895 | E37: =E35/E36 -> 0.14028683 | F37: =F35/F36 -> 0.13884218
A38: Historical range: 12% - 15% (avg ~13.5%–14.7%)
A41: Intangible Amortization Rate
A43: Driver | B43: Value
A44: Amortization Rate | B44: =2.4% -> 0.024
A47: Amortization Rate Analysis (% of Intangibles)
B48: FY2021 | C48: FY2022 | D48: FY2023 | E48: FY2024 | F48: FY2025
A49: Amortization | B49: 89 | C49: 114 | D49: 105 | E49: 123 | F49: 120
A50: Average Intangibles | B50: =(B52+B51)/2 -> 1065.5 | C50: =(C52+C51)/2 -> 1840 | D50: =(D52+D51)/2 -> 3642 | E50: =(E52+E51)/2 -> 5173 | F50: =(F52+F51)/2 -> 5043
A51: Ending Intangible Assets | B51: 1641 | C51: 2039 | D51: 5245 | E51: 5101 | F51: 4985
A52: Beginning Intangible Assets | B52: 490 | C52: 1641 | D52: 2039 | E52: 5245 | F52: 5101
A53: Amortization (%) | B53: =B49/B50 -> 0.08352886 | C53: =C49/C50 -> 0.061956522 | D53: =D49/D50 -> 0.028830313 | E53: =E49/E50 -> 0.023777305 | F53: =F49/F50 -> 0.02379536
A54: Historical range: 2,4% – 8,4% (declining trend; recent ~2,3%–2,9%)
A57: Revenue Growth Assumptions
...

Sheet Historical Financials
C1: Historical Results | H1: Forecast Period
A2: MR Price Group | B2: 2021A | C2: 2022A | D2: 2023A | E2: 2024A | F2: 2025A | G2: 2026E | H2: 2027E | I2: 2028E | J2: 2029E | K2: 2030E
A3: Income Statement
A4: Line Item
A5: Revenue | B5: =B6+B9 -> 22827 | C5: =C6+C9 -> 28083 | D5: =D6+D9 -> 32853 | E5: =E6+E9 -> 37944 | F5: =F6+F9 -> 40933
A6: Retail Sales | B6: =SUM(B7:B8) -> 21690 | C6: =SUM(C7:C8) -> 26683 | D6: =SUM(D7:D8) -> 31498 | E6: =SUM(E7:E8) -> 36586 | F6: =SUM(F7:F8) -> 39439
A7: Cash Sales | B7: =18740 -> 18740 | C7: =22982 -> 22982 | D7: =27494 -> 27494 | E7: =32513 -> 32513 | F7: =35204 -> 35204
A8: Credit Sales | B8: =2950 -> 2950 | C8: =3701 -> 3701 | D8: =4004 -> 4004 | E8: =4073 -> 4073 | F8: =4235 -> 4235
A9: Other revenue | B9: =1137 -> 1137 | C9: =1400 -> 1400 | D9: =1355 -> 1355 | E9: =1358 -> 1358 | F9: =1494 -> 1494
A10: Cost of Sales | B10: -12540 | C10: -15820 | D10: -19144 | E10: -22144 | F10: -23574
A11: Gross Profit | B11: =B5+B10 -> 10287 | C11: =C5+C10 -> 12263 | D11: =D5+D10 -> 13709 | E11: =E5+E10 -> 15800 | F11: =F5+F10 -> 17359
A12: Other income | B12: 0 | C12: 0 | D12: 0 | E12: 0 | F12: 0
A13: Selling Expenses | B13: -4377 | C13: -5049 | D13: -6323 | E13: -7665 | F13: -8464
A14: Administrative & Other Expenses | B14: -1772 | C14: -2050 | D14: -2281 | E14: -2667 | F14: -2897
A15: Total Operating Expenses | B15: =SUM(B13:B14) -> -6149 | C15: =SUM(C13:C14) -> -7099 | D15: =SUM(D13:D14) -> -8604 | E15: =SUM(E13:E14) -> -10332 | F15: =SUM(F13:F14) -> -11361
A16: Operating Profit (EBIT) | B16: =B11+B12+B15 -> 4138 | C16: =C11+C12+C15 -> 5164 | D16: =D11+D12+D15 -> 5105 | E16: =E11+E12+E15 -> 5468 | F16: =F11+F12+F15 -> 5998
A17: Less: Tax Expense | B17: =B16*0.27 -> 1117.26 | C17: =C16*0.27 -> 1394.28 | D17: =D16*0.27 -> 1378.35 | E17: =E16*0.27 -> 1476.36 | F17: =F16*0.27 -> 1619.46
A18: Net Income | B18: =B16-B17 -> 3020.74 | C18: =C16-C17 -> 3769.72 | D18: =D16-D17 -> 3726.65 | E18: =E16-E17 -> 3991.64 | F18: =F16-F17 -> 4378.54
A21: Balance Sheet
A22: Non-Current Assets | B22: =SUM(B23:B24) -> 3877 | C22: =SUM(C23:C24) -> 4557 | D22: =SUM(D23:D24) -> 8843 | E22: =SUM(E23:E24) -> 9173 | F22: =SUM(F23:F24) -> 9239
A23: Property, Plant and Equipment (Net) | B23: 2236 | C23: 2518 | D23: 3598 | E23: 4072 | F23: 4254
A24: Intangible Assets | B24: 1641 | C24: 2039 | D24: 5245 | E24: 5101 | F24: 4985
A25: Current Assets | B25: =SUM(B26:B28) -> 10402 | C25: =SUM(C26:C28) -> 11119 | D25: =SUM(D26:D28) -> 11496 | E25: =SUM(E26:E28) -> 12845 | F25: =SUM(F26:F28) -> 15175
A26: Cash and Cash Equivalents | B26: =4949 -> 4949 | C26: =4612 -> 4612 | D26: =1442 -> 1442 | E26: =2798 -> 2798 | F26: =4147 -> 4147
A27: Inventories | B27: 3298 | C27: 3956 | D27: 7321 | E27: 7078 | F27: 7894
A28: Trade and Other Receivables (operating) | B28: 2155 | C28: 2551 | D28: 2733 | E28: 2969 | F28: 3134
A29: Current Liabilities | B29: =SUM(B30) -> -2542 | C29: =SUM(C30) -> -2895 | D29: =SUM(D30) -> -4877 | E29: =SUM(E30) -> -5175 | F29: =SUM(F30) -> -6424
A30: Trade and Other Payables (operating) | B30: -2542 | C30: -2895 | D30: -4877 | E30: -5175 | F30: -6424
A32: Lease Items
A33: Right-of-Use Assets | B33: 5000 | C33: 6315 | D33: 7737 | E33: 7237 | F33: 7187
A34: Lease Liabilities | B34: 4776 | C34: 5951 | D34: 7028 | E34: 6512 | F34: 6355
A37: Cash Flow Statement
A38: Non-Cash Adjustments | B38: =SUM(B39) -> 1698 | C38: =SUM(C39) -> 1932 | D38: =SUM(D39) -> 2323 | E38: =SUM(E39) -> 2919 | F38: =SUM(F39) -> 3113
A39: Total Depreciation and Amortization | B39: 1698 | C39: 1932 | D39: 2323 | E39: 2919 | F39: 3113
A40: Investing Activities | B40: =SUM(B41:B42) -> -1952 | C40: =SUM(C41:C42) -> -670 | D40: =SUM(D41:D42) -> -4302 | E40: =SUM(E41:E42) -> -981 | F40: =SUM(F41:F42) -> -829
A41: Net CAPEX (PPE + Intangibles) | B41: -441 | C41: -670 | D41: -837 | E41: -981 | F41: -829
A42: Acquisition (Studio 88) | B42: -1511 | D42: -3465
A43: Financing Activities | B43: =SUM(B44:B45) -> -1726 | C43: =SUM(C44:C45) -> -3257 | D43: =SUM(D44:D45) -> -3778 | E43: =SUM(E44:E45) -> -4000 | F43: =SUM(F44:F45) -> -4456
A44: Dividends Paid | B44: -552 | C44: -1959 | D44: -2192 | E44: -1911 | F44: -2178
A45: Repayment of Lease Liability (capital portion) | B45: -1174 | C45: -1298 | D45: -1586 | E45: -2089 | F45: -2278

Sheet Historical Ratios
C1: Historical Results | H1: Forecast Period
A2: Mr Price Group | B2: 2021A | C2: 2022A | D2: 2023A | E2: 2024A | F2: 2025A | G2: 2026E | H2: 2027E | I2: 2028E | J2: 2029E | K2: 2030E
A3: Growth Ratios
A4: Revenue Growth % | C4: =('Historical Financials'!C5/'Historical Financials'!B5)-1 -> 0.23025365 | D4: =('Historical Financials'!D5/'Historical Financials'!C5)-1 -> 0.16985365 | E4: =('Historical Financials'!E5/'Historical Financials'!D5)-1 -> 0.15496302 | F4: =('Historical Financials'!F5/'Historical Financials'!E5)-1 -> 0.078773983
A5: Gross Profit Growth % | C5: =('Historical Financials'!C11/'Historical Financials'!B11)-1 -> 0.1920871 | D5: =('Historical Financials'!D11/'Historical Financials'!C11)-1 -> 0.11791568 | E5: =('Historical Financials'!E11/'Historical Financials'!D11)-1 -> 0.15252754 | F5: =('Historical Financials'!F11/'Historical Financials'!E11)-1 -> 0.098670886
A7: Margin Analysis
A8: Gross Margin % | B8: ='Historical Financials'!B11/'Historical Financials'!B5 -> 0.45065055 | C8: ='Historical Financials'!C11/'Historical Financials'!C5 -> 0.43666987 | D8: ='Historical Financials'!D11/'Historical Financials'!D5 -> 0.41728305 | E8: ='Historical Financials'!E11/'Historical Financials'!E5 -> 0.41640312 | F8: ='Historical Financials'!F11/'Historical Financials'!F5 -> 0.42408326
A9: OpEx % of Revenue | B9: =-('Historical Financials'!B15+'Historical Financials'!B39)/'Historical Financials'!B5 -> 0.19498839 | C9: =-('Historical Financials'!C15+'Historical Financials'!C39)/'Historical Financials'!C5 -> 0.18399031 | D9: =-('Historical Financials'!D15+'Historical Financials'!D39)/'Historical Financials'!D5 -> 0.19118498 | E9: =-('Historical Financials'!E15+'Historical Financials'!E39)/'Historical Financials'!E5 -> 0.19536686 | F9: =-('Historical Financials'!F15+'Historical Financials'!F39)/'Historical Financials'!F5 -> 0.20150001
A10: EBIT Margin % | B10: ='Historical Financials'!B16/'Historical Financials'!B5 -> 0.18127656 | C10: ='Historical Financials'!C16/'Historical Financials'!C5 -> 0.18388349 | D10: ='Historical Financials'!D16/'Historical Financials'!D5 -> 0.15538916 | E10: ='Historical Financials'!E16/'Historical Financials'!E5 -> 0.14410711 | F10: ='Historical Financials'!F16/'Historical Financials'!F5 -> 0.14653214
A12: Working Capital Efficiency
A13: Inventory Days | B13: =('Historical Financials'!B27/ABS('Historical Financials'!B10)*365) -> 95.994418 | C13: =('Historical Financials'!C27/ABS('Historical Financials'!C10)*365) -> 91.273072 | D13: =('Historical Financials'!D27/ABS('Historical Financials'!D10)*365) -> 139.58238 | E13: =('Historical Financials'!E27/ABS('Historical Financials'!E10)*365) -> 116.66682 | F13: =('Historical Financials'!F27/ABS('Historical Financials'!F10)*365) -> 122.22406
A14: Debtor (Receivable) Days | B14: =('Historical Financials'!B28/'Historical Financials'!B8) * 365 -> 266.63559 | C14: =('Historical Financials'!C28/'Historical Financials'!C8) * 365 -> 251.58471 | D14: =('Historical Financials'!D28/'Historical Financials'!D8) * 365 -> 249.13711 | E14: =('Historical Financials'!E28/'Historical Financials'!E8) * 365 -> 266.06555 | F14: =('Historical Financials'!F28/'Historical Financials'!F8) * 365 -> 270.10862
A15: Creditor (Payable) Days | B15: =ABS('Historical Financials'!B30)/ABS('Historical Financials'!B10) * 365 -> 73.989633 | C15: =ABS('Historical Financials'!C30)/ABS('Historical Financials'!C10) * 365 -> 66.793616 | D15: =ABS('Historical Financials'!D30)/ABS('Historical Financials'!D10) * 365 -> 92.985008 | E15: =ABS('Historical Financials'!E30)/ABS('Historical Financials'!E10) * 365 -> 85.29963 | F15: =ABS('Historical Financials'!F30)/ABS('Historical Financials'!F10) * 365 -> 99.463816
A16: Cash Conversion Cycle | B16: =B13+B14-B15 -> 288.64038 | C16: =C13+C14-C15 -> 276.06416 | D16: =D13+D14-D15 -> 295.73448 | E16: =E13+E14-E15 -> 297.43274 | F16: =F13+F14-F15 -> 292.86886
A18: Investment Ratios
A19: Capex as % of Revenue | B19: =ABS('Historical Financials'!B41/'Historical Financials'!B5) -> 0.019319227 | C19: =ABS('Historical Financials'!C41/'Historical Financials'!C5) -> 0.02385785 | D19: =ABS('Historical Financials'!D41/'Historical Financials'!D5) -> 0.025477125 | E19: =ABS('Historical Financials'!E41/'Historical Financials'!E5) -> 0.02585389 | F19: =ABS('Historical Financials'!F41/'Historical Financials'!F5) -> 0.020252608
A20: Dividend Payout Ratio | B20: =ABS('Historical Financials'!B44/'Historical Financials'!B18) -> 0.18273668 | C20: =ABS('Historical Financials'!C44/'Historical Financials'!C18) -> 0.51966724 | D20: =ABS('Historical Financials'!D44/'Historical Financials'!D18) -> 0.58819583 | E20: =ABS('Historical Financials'!E44/'Historical Financials'!E18) -> 0.47875059 | F20: =ABS('Historical Financials'!F44/'Historical Financials'!F18) -> 0.49742608

Sheet Forecast Model
B1: Forecast Period
A2: Mr Price Group - Forecast (R'm) | B2: 2026E | C2: 2027E | D2: 2028E | E2: 2029E | F2: 2030E
A3: Forecast Financial Statements
A4: All figures in R'm
A6: Income Statement
A7: Revenue | B7: ='Historical Financials'!F5*(1+Assumptions!B60) -> 44002.975 | C7: =B7*(1+Assumptions!B61) -> 47083.183 | D7: =C7*(1+Assumptions!B62) -> 49908.174 | E7: =D7*(1+Assumptions!B63) -> 52403.583 | F7: =E7*(1+Assumptions!B64) -> 54499.726
A8: Retail sales | B8: =B7-B11 -> 42418.868 | C8: =C7-C11 -> 45388.189 | D8: =D7-D11 -> 48161.388 | E8: =E7-E11 -> 50569.458 | F8: =F7-F11 -> 52592.236
A9: Cash sales | B9: =B8-B10 -> 37964.887 | C9: =C8-C10 -> 40713.205 | D9: =D8-D10 -> 43248.927 | E9: =E8-E10 -> 45512.512 | F9: =F8-F10 -> 47333.012
A10: Credit Sales | B10: =B8*Assumptions!B93 -> 4453.9811 | C10: =C8*Assumptions!B94 -> 4674.9834 | D10: =D8*Assumptions!B95 -> 4912.4616 | E10: =E8*Assumptions!B96 -> 5056.9458 | F10: =F8*Assumptions!B97 -> 5259.2236
A11: Other revenue | B11: =B7*Assumptions!B114 -> 1584.1071 | C11: =C7*Assumptions!B115 -> 1694.9946 | D11: =D7*Assumptions!B116 -> 1746.7861 | E11: =E7*Assumptions!B117 -> 1834.1254 | F11: =F7*Assumptions!B118 -> 1907.4904
A12: Cost of Sales | B12: =B7*(1-Assumptions!B132) -> 25081.696 | C12: =C7*(1-Assumptions!B132) -> 26837.414 | D12: =D7*(1-Assumptions!B132) -> 28447.659 | E12: =E7*(1-Assumptions!B132) -> 29870.042 | F12: =F7*(1-Assumptions!B132) -> 31064.844
A13: Gross Profit | B13: =B7-B12 -> 18921.279 | C13: =C7-C12 -> 20245.769 | D13: =D7-D12 -> 21460.515 | E13: =E7-E12 -> 22533.541 | F13: =F7-F12 -> 23434.882
A14: Other Income | B14: ='Historical Financials'!B12 -> 0 | C14: ='Historical Financials'!C12 -> 0 | D14: ='Historical Financials'!D12 -> 0 | E14: 0 | F14: 0
A15: Operating Expenses | B15: =B7*Assumptions!B194 -> 13640.922 | C15: =C7*Assumptions!B195 -> 14360.371 | D15: =D7*Assumptions!B196 -> 14972.452 | E15: =E7*Assumptions!B197 -> 15459.057 | F15: =F7*Assumptions!B198 -> 15804.921
A16: EBIT | B16: =B13-B15 -> 5280.357 | C16: =C13-C15 -> 5885.3979 | D16: =D13-D15 -> 6488.0627 | E16: =E13-E15 -> 7074.4837 | F16: =F13-F15 -> 7629.9617
A17: EBIT Margin % | B17: =B16/B7 -> 0.12 | C17: =C16/C7 -> 0.125 | D17: =D16/D7 -> 0.13 | E17: =E16/E7 -> 0.135 | F17: =F16/F7 -> 0.14
A18: Less: Tax | B18: =B16*Assumptions!B227 -> 1425.6964 | C18: =C16*Assumptions!B227 -> 1589.0574 | D18: =D16*Assumptions!B227 -> 1751.7769 | E18: =E16*Assumptions!B227 -> 1910.1106 | F18: =F16*Assumptions!B227 -> 2060.0897
A19: Net Income | B19: =B16-B18 -> 3854.6606 | C19: =C16-C18 -> 4296.3405 | D19: =D16-D18 -> 4736.2857 | E19: =E16-E18 -> 5164.3731 | F19: =F16-F18 -> 5569.872
A22: Balance Sheet
A23: Non-Current Assets
A24: PPE | B24: =B54 -> 4318.4846 | C24: =C54 -> 4420.1445 | D24: =D54 -> 4549.9469 | E24: =E54 -> 4699.0081 | F24: =F54 -> 4858.6428
A25: Intangible Assets | B25: =B59 -> 4865.36 | C25: =C59 -> 4748.5914 | D25: =D59 -> 4634.6252 | E25: =E59 -> 4523.3942 | F25: =F59 -> 4414.8327
A26: Total Non-Current Assets | B26: =SUM(B24:B25) -> 9183.8446 | C26: =SUM(C24:C25) -> 9168.7359 | D26: =SUM(D24:D25) -> 9184.5721 | E26: =SUM(E24:E25) -> 9222.4022 | F26: =SUM(F24:F25) -> 9273.4755
A28: Current Assets
A29: Cash | B29: =B86 -> 2973.2454 | C29: =C86 -> 2136.7788 | D29: =D86 -> 1444.7688 | E29: =E86 -> 982.65328 | F29: =F86 -> 645.78445
A30: Inventories | B30: =Assumptions!$B$164/365*'Forecast Model'!B12 -> 8246.037 | C30: =Assumptions!$B$164/365*'Forecast Model'!C12 -> 8823.2595 | D30: =Assumptions!$B$164/365*'Forecast Model'!D12 -> 9352.6551 | E30: =Assumptions!$B$164/365*'Forecast Model'!E12 -> 9820.2879 | F30: =Assumptions!$B$164/365*'Forecast Model'!F12 -> 10213.099
A31: Receivables | B31: =Assumptions!$B$163/365*B10 -> 3172.6989 | C31: =Assumptions!$B$163/365*C10 -> 3330.1252 | D31: =Assumptions!$B$163/365*D10 -> 3499.2877 | E31: =Assumptions!$B$163/365*E10 -> 3602.2079 | F31: =Assumptions!$B$163/365*F10 -> 3746.2963
A32: Total Current Assets | B32: =SUM(B29:B31) -> 14391.981 | C32: =SUM(C29:C31) -> 14290.164 | D32: =SUM(D29:D31) -> 14296.712 | E32: =SUM(E29:E31) -> 14405.149 | F32: =SUM(F29:F31) -> 14605.18
A34: Total Assets | B34: =B26+B32 -> 23575.826 | C34: =C26+C32 -> 23458.899 | D34: =D26+D32 -> 23481.284 | E34: =E26+E32 -> 23627.551 | F34: =F26+F32 -> 23878.656
A36: Current Liabilities
A37: Payables | B37: =- Assumptions!$B$165/365*'Forecast Model'!B12 -> -6321.9617 | C37: =- Assumptions!$B$165/365*'Forecast Model'!C12 -> -6764.499 | D37: =- Assumptions!$B$165/365*'Forecast Model'!D12 -> -7170.3689 | E37: =- Assumptions!$B$165/365*'Forecast Model'!E12 -> -7528.8874 | F37: =- Assumptions!$B$165/365*'Forecast Model'!F12 -> -7830.0429
A39: Lease Items
A40: Right-of-Use Assets | B40: ='Historical Financials'!$F$33 -> 7187 | C40: ='Historical Financials'!$F$33 -> 7187 | D40: ='Historical Financials'!$F$33 -> 7187 | E40: ='Historical Financials'!$F$33 -> 7187 | F40: ='Historical Financials'!$F$33 -> 7187
A41: Lease Liabilities | B41: ='Historical Financials'!$F$34 -> 6355 | C41: ='Historical Financials'!$F$34 -> 6355 | D41: ='Historical Financials'!$F$34 -> 6355 | E41: ='Historical Financials'!$F$34 -> 6355 | F41: ='Historical Financials'!$F$34 -> 6355
A43: Total Liabilities | B43: =B37+B41 -> 33.038332 | C43: =C37+C41 -> -409.49899 | D43: =D37+D41 -> -815.36892 | E43: =E37+E41 -> -1173.8874 | F43: =F37+F41 -> -1475.0429
A44: Equity (Plug) | B44: =B34-B43 -> 23542.788 | C44: =C34-C43 -> 23868.398 | D44: =D34-D43 -> 24296.653 | E44: =E34-E43 -> 24801.439 | F44: =F34-F43 -> 25353.699
A45: Total Liabilities + Equity | B45: =B43+B44 -> 23575.826 | C45: =C43+C44 -> 23458.899 | D45: =D43+D44 -> 23481.284 | E45: =E43+E44 -> 23627.551 | F45: =F43+F44 -> 23878.656
A47: Balance Check | B47: =B34-B45 -> 0 | C47: =C34-C45 -> 0 | D47: =D34-D45 -> 0 | E47: =E34-E45 -> 0 | F47: =F34-F45 -> 0
A49: Supporting Schedule
A50: PPE Roll-Forward
...

Sheet DCF Valuation
B1: Forecast Period | Z1: =Assumptions!B219 -> 0.138515
A2: Mr Price Group (R'm)-DCF Valuation | B2: 2026E | C2: 2027E | D2: 2028E | E2: 2029E | F2: 2030E | Z2: =Assumptions!B65 -> 0.03
A4: Unlevered Free Cash Flow (FCFF) (R'm)
A5: EBIT | B5: ='Forecast Model'!B16 -> 5280.357 | C5: ='Forecast Model'!C16 -> 5885.3979 | D5: ='Forecast Model'!D16 -> 6488.0627 | E5: ='Forecast Model'!E16 -> 7074.4837 | F5: ='Forecast Model'!F16 -> 7629.9617
A6: Tax on EBIT | B6: =B5*Assumptions!$B$227 -> 1425.6964 | C6: =C5*Assumptions!$B$227 -> 1589.0574 | D6: =D5*Assumptions!$B$227 -> 1751.7769 | E6: =E5*Assumptions!$B$227 -> 1910.1106 | F6: =F5*Assumptions!$B$227 -> 2060.0897
A7: NOPAT | B7: =B5-B6 -> 3854.6606 | C7: =C5-C6 -> 4296.3405 | D7: =D5-D6 -> 4736.2857 | E7: =E5-E6 -> 5164.3731 | F7: =F5-F6 -> 5569.872
A8: + Depreciation and Amortization | B8: ='Forecast Model'!B65 -> 715.2 | C8: ='Forecast Model'!C65 -> 721.35649 | D8: ='Forecast Model'!D65 -> 732.78643 | E8: ='Forecast Model'!E65 -> 748.22357 | F8: ='Forecast Model'!F65 -> 766.42259
A9: - CAPEX | B9: =-('Forecast Model'!B52) -> -660.04462 | C9: =-('Forecast Model'!C52) -> -706.24775 | D9: =-('Forecast Model'!D52) -> -748.62261 | E9: =-('Forecast Model'!E52) -> -786.05374 | F9: =-('Forecast Model'!F52) -> -817.49589
A10: - Change in Working Capital | B10: ='Forecast Model'!B66+'Forecast Model'!B67+'Forecast Model'!B68 -> -492.77418 | C10: ='Forecast Model'!C66+'Forecast Model'!C67+'Forecast Model'!C68 -> -292.11157 | D10: ='Forecast Model'!D66+'Forecast Model'!D67+'Forecast Model'!D68 -> -292.68816 | E10: ='Forecast Model'!E66+'Forecast Model'!E67+'Forecast Model'!E68 -> -212.03454 | F10: ='Forecast Model'!F66+'Forecast Model'!F67+'Forecast Model'!F68 -> -235.74434
A11: FCFF | B11: =B7+B8-B9-B10 -> 5722.6794 | C11: =C7+C8-C9-C10 -> 6016.0563 | D11: =D7+D8-D9-D10 -> 6510.3829 | E11: =E7+E8-E9-E10 -> 6910.685 | F11: =F7+F8-F9-F10 -> 7389.5348
A13: Notes:
A14: Tax rate from assumptions sheet
A15: CAPEX forecast as % of revenue
A16: Working capital based on days assumptions
A18: Discount Factor | B18: =1/(1+Z1) -> 0.87833713 | C18: =1/(1+Assumptions!B219)^2 -> 0.77147612 | D18: =1/(1+Assumptions!B219)^3 -> 0.67761612 | E18: =1/(1+Assumptions!B219)^4 -> 0.5951754 | F18: =1/(1+Assumptions!B219)^5 -> 0.52276465
A19: Present Value of FCFF | B19: =B11*B18 -> 5026.4418 | C19: =C11*C18 -> 4641.2437 | D19: =D11*D18 -> 4411.5404 | E19: =E11*E18 -> 4113.0697 | F19: =F11*F18 -> 3862.9876
A21: Sum of PV of FCFF | B21: =SUM(B19:F19) -> 22055.283
A23: Terminal Value (2030) | B23: =F11*(1+$Z$2)/($Z$1-$Z$2) -> 70139.805
A24: Present Value of Terminal Value | B24: =B23*F18 -> 36666.611
A26: Enterprise Value | B26: =B21+B24 -> 58721.894
A28: Bridge to Equity Value
A29: Shares Outstanding (millions) | B29: 257.48
A30: Enterprise Value | B30: =B26 -> 58721.894
A31: + Cash (FY2025 Actual) | B31: ='Historical Financials'!F26 -> 4147
A32: - Lease Liabilities (IFRS 16) | B32: ='Historical Financials'!F34 -> 6355
A33: Equity Value | B33: =B30+B31-B32 -> 56513.894
A34: Implied Share Price = Equity Value / Shares | B34: =B33/B29 -> 219.48848
A37: Share Price Sensitivity
D38: Terminal Growth
B39: =B34 -> 219.48848 | C39: 0.02 | D39: 0.025 | E39: 0.03 | F39: 0.035 | G39: 0.04
B40: 0.1 | C40: 269.05534 | D40: 282.80815 | E40: 298.52564 | F40: 316.6612 | G40: 337.81936
B41: 0.105 | C41: 257.71162 | D41: 269.90161 | E41: 283.71692 | F41: 299.50586 | G41: 317.72386
B42: 0.11 | C42: 247.61898 | D42: 258.50355 | E42: 270.7487 | F42: 284.62653 | G42: 300.4869
A43: WACC | B43: 0.115 | C43: 238.58 | D43: 248.36269 | E43: 259.2963 | F43: 271.5966 | G43: 285.53694
B44: 0.12 | C44: 230.43673 | D44: 239.28064 | E44: 249.10721 | F44: 260.08984 | G44: 272.4453
B45: 0.125 | C45: 223.06134 | D45: 231.09869 | E45: 239.98208 | F45: 249.85251 | G45: 260.88418
B46: 0.13 | C46: 216.34919 | D46: 223.68835 | E46: 231.76143 | F46: 240.6843 | G46: 250.5986
B47: 0.135 | C47: 210.21388 | D47: 216.9445 | E47: 224.31614 | F47: 232.42493 | G47: 241.38729
B48: 0.14 | C48: 204.58339 | D48: 210.7803 | E48: 217.54057 | F48: 224.94468 | G48: 233.0892

Sheet Operational Sensitivity
Z1: =0.06+Assumptions!$B$249 -> 0.06
A2: Operational Sensitivity (Revenue Growth Vs OpEx %) | Z2: =0.3+Assumptions!$B$250 -> 0.3
F3: Revenue Growth
B4: ='DCF Valuation'!B34 -> 219.48848 | C4: 0.03 | D4: 0.04 | E4: 0.05 | F4: 0.06 | G4: 0.07 | H4: 0.08 | I4: 0.09
B5: 0.25 | C5: 218.79156 | D5: 220.62189 | E5: 222.45222 | F5: 224.28256 | G5: 226.11289 | H5: 227.94322 | I5: 229.77355
A6: OpEx % | B6: 0.26 | C6: 217.85988 | D6: 219.68117 | E6: 221.50245 | F6: 223.32374 | G6: 225.14503 | H6: 226.96631 | I6: 228.7876
B7: 0.27 | C7: 216.9282 | D7: 218.74044 | E7: 220.55268 | F7: 222.36493 | G7: 224.17717 | H7: 225.98941 | I7: 227.80165
B8: 0.28 | C8: 215.99653 | D8: 217.79972 | E8: 219.60292 | F8: 221.40611 | G8: 223.20931 | H8: 225.0125 | I8: 226.8157
B9: 0.29 | C9: 215.06485 | D9: 216.859 | E9: 218.65315 | F9: 220.4473 | G9: 222.24145 | H9: 224.03559 | I9: 225.82974
B10: 0.3 | C10: 214.13317 | D10: 215.91827 | E10: 217.70338 | F10: 219.48848 | G10: 221.27358 | H10: 223.05869 | I10: 224.84379
